============================= test session starts ==============================
platform darwin -- Python 3.8.15, pytest-7.1.2, pluggy-1.0.0
rootdir: /Users/sandrineveloso/Documents/COURS_ENSEIGNEMENT_FORMATION/FORMATIONS/2103 OPENSCLASSROOM/7_PROJECT7/LIVRABLES/DataScientist_PRJ7
plugins: anyio-3.5.0, notebook-0.6.1
collected 0 items / 1 error

==================================== ERRORS ====================================
________________ ERROR collecting api/backend/test_fast_api.py _________________
api/backend/test_fast_api.py:3: in <module>
    from fast_api import app
api/backend/fast_api.py:3: in <module>
    from components.model import model_prediction
api/backend/components/model.py:11: in <module>
    application_test = pd.read_csv(path + "application_test_df.csv")
../../../../../../../opt/anaconda3/envs/OCR_env/lib/python3.8/site-packages/pandas/util/_decorators.py:211: in wrapper
    return func(*args, **kwargs)
../../../../../../../opt/anaconda3/envs/OCR_env/lib/python3.8/site-packages/pandas/util/_decorators.py:331: in wrapper
    return func(*args, **kwargs)
../../../../../../../opt/anaconda3/envs/OCR_env/lib/python3.8/site-packages/pandas/io/parsers/readers.py:950: in read_csv
    return _read(filepath_or_buffer, kwds)
../../../../../../../opt/anaconda3/envs/OCR_env/lib/python3.8/site-packages/pandas/io/parsers/readers.py:605: in _read
    parser = TextFileReader(filepath_or_buffer, **kwds)
../../../../../../../opt/anaconda3/envs/OCR_env/lib/python3.8/site-packages/pandas/io/parsers/readers.py:1442: in __init__
    self._engine = self._make_engine(f, self.engine)
../../../../../../../opt/anaconda3/envs/OCR_env/lib/python3.8/site-packages/pandas/io/parsers/readers.py:1735: in _make_engine
    self.handles = get_handle(
../../../../../../../opt/anaconda3/envs/OCR_env/lib/python3.8/site-packages/pandas/io/common.py:856: in get_handle
    handle = open(
E   FileNotFoundError: [Errno 2] No such file or directory: '../../data/application_test_df.csv'
=============================== warnings summary ===============================
../../../../../../../opt/anaconda3/envs/OCR_env/lib/python3.8/site-packages/xgboost/compat.py:36
  /Users/sandrineveloso/opt/anaconda3/envs/OCR_env/lib/python3.8/site-packages/xgboost/compat.py:36: FutureWarning: pandas.Int64Index is deprecated and will be removed from pandas in a future version. Use pandas.Index with the appropriate dtype instead.
    from pandas import MultiIndex, Int64Index

-- Docs: https://docs.pytest.org/en/stable/how-to/capture-warnings.html
=========================== short test summary info ============================
ERROR api/backend/test_fast_api.py - FileNotFoundError: [Errno 2] No such fil...
!!!!!!!!!!!!!!!!!!!! Interrupted: 1 error during collection !!!!!!!!!!!!!!!!!!!!
========================= 1 warning, 1 error in 1.64s ==========================
